<sdf version="1.6">
  <world name="diff_drive">

    <physics name="1ms" type="ignored">
      <max_step_size>0.001</max_step_size>
      <real_time_factor>1.0</real_time_factor>
    </physics>
    <plugin
      filename="ignition-gazebo-physics-system"
      name="gz::sim::systems::Physics">
    </plugin>
    <plugin
      filename="ignition-gazebo-user-commands-system"
      name="gz::sim::systems::UserCommands">
    </plugin>
    <plugin
      filename="ignition-gazebo-scene-broadcaster-system"
      name="gz::sim::systems::SceneBroadcaster">
    </plugin>

    <light type="directional" name="sun">
      <cast_shadows>true</cast_shadows>
      <pose>0 0 10 0 0 0</pose>
      <diffuse>1 1 1 1</diffuse>
      <specular>0.5 0.5 0.5 1</specular>
      <attenuation>
        <range>1000</range>
        <constant>0.9</constant>
        <linear>0.01</linear>
        <quadratic>0.001</quadratic>
      </attenuation>
      <direction>-0.5 0.1 -0.9</direction>
    </light>

    <model name="ground_plane">
      <static>true</static>
      <link name="link">
        <collision name="collision">
          <geometry>
            <plane>
              <normal>0 0 1</normal>
              <size>100 100</size>
            </plane>
          </geometry>
        </collision>
        <visual name="visual">
          <geometry>
            <plane>
              <normal>0 0 1</normal>
              <size>100 100</size>
            </plane>
          </geometry>
          <material>
            <ambient>0.8 0.8 0.8 1</ambient>
            <diffuse>0.8 0.8 0.8 1</diffuse>
            <specular>0.8 0.8 0.8 1</specular>
          </material>
        </visual>
      </link>
    </model>

    <model name='kris_robot>
      <pose>0 2 0.325 0 -0 0</pose>
	<link name="base_link">
		<visual>
			<geometry>
				<cylinder length="0.08" radius="0.055" />
			</geometry>
			<origin rpy="0 0 0" xyz="0 0 0.041" />
			<material name="white">
				<color rgba="1 1 1 1" />
			</material>
		</visual>
		<inertial>
			<origin xyz="0 0 0" rpy="0 0 0.041"/>
			<mass value="0.25"/>
			<inertia
				ixx="1.0" ixy="0.0" ixz="0.0"
				iyy="1.0" iyz="0.0"
				izz="1.0"/>
		</inertial>
	</link>
	<joint name="base_link_to_lwheel" type="revolute">
		<parent link="base_link" />
		<child link="lwheel" />
		<origin rpy="1.5708 1.5708 0" xyz="0.050 0 0.02" />
		<axis>
          <xyz>0 0 1</xyz>
          <limit>
            <lower>-1.79769e+308</lower>
            <upper>1.79769e+308</upper>
          </limit>
        </axis>
	</joint>
	<link name="lwheel">
		<visual>
			<geometry>
				<cylinder length="0.025" radius="0.0325" />
			</geometry>
			<origin rpy="1.5708 1.5708 0" xyz="0 0.050 0.02" />
			<material name="black">
				<color rgba="0 0 0 1" />
			</material>
		</visual>
		<inertial>
			<origin xyz="1.5708 1.5708 0" rpy="0 0.050 0.02"/>
			<mass value="0.1"/>
			<inertia
				ixx="1.0" ixy="0.0" ixz="0.0"
				iyy="1.0" iyz="0.0"
				izz="1.0"/>
		</inertial>
	</link>
	<joint name="base_link_to_rwheel" type="revolute">
		<parent link="base_link" />
		<child link="rwheel" />
		<origin rpy="1.5708 1.5708 0" xyz="-0.050 0 0.02" />
		<axis>
          <xyz>0 0 1</xyz>
          <limit>
            <lower>-1.79769e+308</lower>
            <upper>1.79769e+308</upper>
          </limit>
        </axis>
	</joint>
	<link name="rwheel">
		<visual>
			<geometry>
				<cylinder length="0.025" radius="0.0325" />
			</geometry>
			<origin rpy="1.5708 1.5708 0" xyz="0 -0.050 0.02" />
			<material name="black">
				<color rgba="0 0 0 1" />
			</material>
		</visual>
		<inertial>
			<origin xyz="1.5708 1.5708 0" rpy="0 -0.050 0.02"/>
			<mass value="0.1"/>
			<inertia
				ixx="1.0" ixy="0.0" ixz="0.0"
				iyy="1.0" iyz="0.0"
				izz="1.0"/>
		</inertial>
	</link>

	<joint name="laser_joint" type="fixed">
        <parent link="base_link"/>
        <child link="laser_frame"/>
        <origin xyz="0.1 0 0.175" rpy="0 0 0"/>
    </joint>

    <link name="laser_frame">
		<visual>
			<geometry>
				<cylinder radius="0.035" length="0.034"/>
			</geometry>
			<material name="red"/>
			<origin xyz="0 0 0.09" rpy="0 0 0"/>
		</visual>
		<inertial>
			<origin xyz="0 0 0.09" rpy="0 0 0"/>
			<mass value="0.05"/>
			<inertia
				ixx="1.0" ixy="0.0" ixz="0.0"
				iyy="1.0" iyz="0.0"
				izz="1.0"/>
		</inertial>
	</link>

	<material name="red">
    	<color rgba="1 0 0 1"/>
	</material>

	<gazebo reference="laser_frame">
        <material>Gazebo/Red</material>

        <sensor name="laser" type="ray">
            <pose> 0 0 0 0 0 0 </pose>
            <visualize>true</visualize>
            <update_rate>10</update_rate>
            <ray>
                <scan>
                    <horizontal>
                        <samples>360</samples>
                        <min_angle>-3.14</min_angle>
                        <max_angle>3.14</max_angle>
                    </horizontal>
                </scan>
                <range>
                    <min>0.3</min>
                    <max>12</max>
                </range>
            </ray>
        </sensor>    

      <plugin
        filename="ignition-gazebo-diff-drive-system"
        name="gz::sim::systems::DiffDrive">
        <left_joint>left_wheel_joint</left_joint>
        <right_joint>right_wheel_joint</right_joint>
        <wheel_separation>1.25</wheel_separation>
        <wheel_radius>0.3</wheel_radius>
        <odom_publish_frequency>1</odom_publish_frequency>
        <max_linear_acceleration>1</max_linear_acceleration>
        <min_linear_acceleration>-1</min_linear_acceleration>
        <max_angular_acceleration>2</max_angular_acceleration>
        <min_angular_acceleration>-2</min_angular_acceleration>
        <max_linear_velocity>0.5</max_linear_velocity>
        <min_linear_velocity>-0.5</min_linear_velocity>
        <max_angular_velocity>1</max_angular_velocity>
        <min_angular_velocity>-1</min_angular_velocity>
      </plugin>

    </model>
  </world>
</sdf>