<robot name="kris_robot">
	<link name="base_link">
		<visual>
			<geometry>
				<cylinder length="0.08" radius="0.055" />
			</geometry>
			<origin rpy="0 0 0" xyz="0 0 0.041" />
			<material name="white">
				<color rgba="1 1 1 1" />
			</material>
		</visual>
	</link>
	<joint name="base_link_to_lwheel" type="continuous">
		<parent link="base_link" />
		<child link="lwheel" />
		<origin rpy="1.5708 1.5708 0" xyz="0.050 0 0.02" />
	</joint>
	<link name="lwheel">
		<visual>
			<geometry>
				<cylinder length="0.025" radius="0.0325" />
			</geometry>
			<origin rpy="1.5708 1.5708 0" xyz="0 0.050 0.02" />
			<material name="black">
				<color rgba="0 0 0 1" />
			</material>
		</visual>
	</link>
	<joint name="base_link_to_rwheel" type="continuous">
		<parent link="base_link" />
		<child link="rwheel" />
		<origin rpy="1.5708 1.5708 0" xyz="-0.050 0 0.02" />
	</joint>
	<link name="rwheel">
		<visual>
			<geometry>
				<cylinder length="0.025" radius="0.0325" />
			</geometry>
			<origin rpy="1.5708 1.5708 0" xyz="0 -0.050 0.02" />
			<material name="black">
				<color rgba="0 0 0 1" />
			</material>
		</visual>
	</link>
</robot>
